Workbook

Sheet Summary
B2: JioSignage Test Report Summary Date: 03-Nov-2025
B3: Solution / Application Name | C3: JioSignage | F3: Jio Signage Android App Version | J3: JS_3.13.apk
B4: JioSignage Portal v 8.7 | C4: https://sit2.jiosignage.jio.com/
B5: Test Device : Model Number | C5: STB : MCM3000 | F5: AOSP _FW _Version | J5: STB-JSB3000-4.75 E
B7: Test Item Name | C7: Test Cases Summary | J7: VIT Rating
C8: Total | D8: PASS | E8: FAIL | F8: NA | G8: NT | H8: EXECUTION % | I8: PASS %
A9: 20 | B9: Login & Profile | C9: =COUNTA('Login & Profile'!A2:A27) -> 26 | D9: =COUNTIF('Login & Profile'!I2:I27,"PASS*") -> 0 | E9: =COUNTIF('Login & Profile'!I2:I27,"FAIL") -> 0 | F9: =COUNTIF('Login & Profile'!I2:I27,"NA") -> 0 | G9: =COUNTIF('Login & Profile'!I2:I27,"NT") -> 0 | H9: =(D9+E9+F9+G9)/C9 -> 0 | I9: =D9/C9 -> 0
A10: 58 | B10: Dashboard | C10: =COUNTA(Dashboard!A2:A73) -> 70 | D10: =COUNTIF(Dashboard!I2:I73,"PASS*") -> 0 | E10: =COUNTIF(Dashboard!I2:I70,"FAIL") -> 0 | F10: =COUNTIF(Dashboard!I2:I70,"NA") -> 0 | G10: =COUNTIF(Dashboard!I2:I68,"NT") -> 0 | H10: =(D10+E10+F10+G10)/C10 -> 0 | I10: =D10/C10 -> 0
A11: 69 | B11: Materials | C11: =COUNTA(Materials!A2:A83) -> 79 | D11: =COUNTIF(Materials!I2:I81,"PASS*") -> 0 | E11: =COUNTIF(Materials!I2:I81,"FAIL") -> 0 | F11: =COUNTIF(Materials!I2:I78,"NA") -> 0 | G11: =COUNTIF(Materials!I2:I78,"NT") -> 0 | H11: =(D11+E11+F11+G11)/C11 -> 0 | I11: =D11/C11 -> 0
A12: 74 | B12: Layout | C12: =COUNTA(Layouts!A2:A217) -> 210 | D12: =COUNTIF(Layouts!I2:I217,"PASS*") -> 0 | E12: =COUNTIF(Layouts!I2:I217,"FAIL") -> 0 | F12: =COUNTIF(Layouts!I2:I217,"NA") -> 0 | G12: =COUNTIF(Layouts!I2:I217,"NT") -> 0 | H12: =(D12+E12+F12+G12)/C12 -> 0 | I12: =D12/C12 -> 0
B13: Layout Approval | C13: =COUNTA(LayoutApproval!A2:A22) -> 20 | D13: =COUNTIF(LayoutApproval!I:I,"PASS*") -> 0 | E13: =COUNTIF(LayoutApproval!I:I,"FAIL") -> 0 | F13: =COUNTIF(LayoutApproval!I:I,"NA") -> 0 | G13: =COUNTIF(LayoutApproval!I:I,"NT") -> 0 | H13: =(D13+E13+F13+G13)/C13 -> 0 | I13: =D13/C13 -> 0
A14: 73 | B14: Playlists | C14: =COUNTA(Playlists!A2:A113) -> 112 | D14: =COUNTIF(Playlists!I2:I120,"PASS*") -> 0 | E14: =COUNTIF(Playlists!I2:I120,"FAIL") -> 0 | F14: =COUNTIF(Playlists!I1:I120,"NA") -> 0 | G14: =COUNTIF(Playlists!I2:I120,"NT") -> 0 | H14: =(D14+E14+F14+G14)/C14 -> 0 | I14: =D14/C14 -> 0
A15: 77 | B15: Schedules | C15: =COUNTA(Schedules!A2:A116) -> 112 | D15: =COUNTIF(Schedules!I2:I116,"PASS*") -> 0 | E15: =COUNTIF(Schedules!I2:I116,"FAIL") -> 0 | F15: =COUNTIF(Schedules!I2:I118,"NA") -> 0 | G15: =COUNTIF(Schedules!I2:I118,"NT") -> 0 | H15: =(D15+E15+F15+G15)/C15 -> 0 | I15: =D15/C15 -> 0
A16: 57 | B16: Displays | C16: =COUNTA(Displays!A2:A87) -> 86 | D16: =COUNTIF(Displays!I:I,"PASS*") -> 0 | E16: =COUNTIF(Displays!I:I,"FAIL") -> 0 | F16: =COUNTIF(Displays!I:I,"NA") -> 0 | G16: =COUNTIF(Displays!I:I,"NT") -> 0 | H16: =(D16+E16+F16+G16)/C16 -> 0 | I16: =D16/C16 -> 0
A17: 98 | B17: User Access | C17: =COUNTA('User Access'!A2:A105) -> 102 | D17: =COUNTIF('User Access'!I2:I103,"PASS*") -> 0 | E17: =COUNTIF('User Access'!I2:I102,"FAIL") -> 0 | F17: =COUNTIF('User Access'!I2:I102,"NA") -> 0 | G17: =COUNTIF('User Access'!I2:I102,"NT") -> 0 | H17: =(D17+E17+F17+G17)/C17 -> 0 | I17: =D17/C17 -> 0
A18: 29 | B18: Display Status | C18: =COUNTA('Display Status'!A2:A48) -> 43 | D18: =COUNTIF('Display Status'!I2:I49,"PASS*") -> 0 | E18: =COUNTIF('Display Status'!I2:I43,"FAIL") -> 0 | F18: =COUNTIF('Display Status'!I2:I43,"NA") -> 0 | G18: =COUNTIF('Display Status'!I2:I43,"NT") -> 0 | H18: =(D18+E18+F18+G18)/C18 -> 0 | I18: =D18/C18 -> 0
B19: Live Monitoring | C19: =COUNTA('Live Monitoring'!A2:A21) -> 17 | D19: =COUNTIF('Live Monitoring'!I2:I18,"Pass") -> 0 | E19: =COUNTIF('Live Monitoring'!I2:I18,"Fail") -> 0 | F19: =COUNTIF('Live Monitoring'!I2:I18,"NA") -> 0 | G19: =COUNTIF('Live Monitoring'!I2:I18,"NT") -> 0 | H19: =(D19+E19+F19+G19)/C19 -> 0 | I19: =D19/C19 -> 0
B20: Reports | C20: =COUNTA(Reports!A2:A75) -> 71 | D20: =COUNTIF(Reports!I2:I75,"PASS*") -> 0 | E20: =COUNTIF(Reports!I2:I71,"FAIL") -> 0 | F20: =COUNTIF(Reports!I2:I71,"NA") -> 0 | G20: =COUNTIF(Reports!I2:I71,"NT") -> 0 | H20: =(D20+E20+F20+G20)/C20 -> 0 | I20: =D20/C20 -> 0
A21: 14 | B21: Emergency Alerts | C21: =COUNTA('Emergenecy Alerts'!A2:A20) -> 15 | D21: =COUNTIF('Emergenecy Alerts'!I2:I16,"PASS*") -> 0 | E21: =COUNTIF('Emergenecy Alerts'!I2:I12,"FAIL") -> 0 | F21: =COUNTIF('Emergenecy Alerts'!I2:I12,"NA") -> 0 | G21: =COUNTIF('Emergenecy Alerts'!I2:I12,"NT") -> 0 | H21: =(D21+E21+F21+G21)/C21 -> 0 | I21: =D21/C21 -> 0
B22: System Test | C22: =COUNTA('System Test'!A2:A19) -> 13 | D22: =COUNTIF('System Test'!I2:I15,"PASS") -> 0 | E22: =COUNTIF('System Test'!I2:I15,"FAIL") -> 0 | F22: =COUNTIF('System Test'!I2:I15,"NA") -> 0 | G22: =COUNTIF('System Test'!I2:I16,"NT") -> 0 | H22: =(D22+E22+F22+G22)/C22 -> 0 | I22: =D22/C22 -> 0
B23: Long Duration | C23: =COUNTA('Long Duration'!A2:A19) -> 14 | D23: =COUNTIF('Long Duration'!F2:F19,"PASS") -> 0 | E23: =COUNTIF('Long Duration'!F2:F19,"FAIL") -> 0 | F23: =COUNTIF('Long Duration'!F2:F19,"NA") -> 0 | G23: =COUNTIF('Long Duration'!F2:F19,"NT") -> 0 | H23: =(D23+E23+F23+G23)/C23 -> 0 | I23: =D23/C23 -> 0
B24: TOTAL | C24: =SUM(C9:C23) -> 990 | D24: =SUM(D9:D23) -> 0 | E24: =SUM(E9:E23) -> 0 | F24: =SUM(F9:F23) -> 0 | G24: =SUM(G9:G23) -> 0 | H24: =(D24+E24+F24+G24)/C24 -> 0 | I24: =D24/C24 -> 0

Sheet Issue_list

Sheet Login & Profile
A1: Sr. No | B1: Test Type | C1: Functionality Name | D1: Sub Functionality | E1: Test Objective | F1: Test Steps | G1: Expected Behaviour | H1: Automation test case name | I1: Result | J1: Comment
A2: TC1 | B2: Functionality | C2: Sign In | D2: Launch Sign In Page | E2: Check that user is able to open Sign In Page | F2: 1. Launch JioSignage Sign In Page : https://digitalsignage.jio.com/users/sign in . | G2: Following are expected behaviour 1. User should be able to launch Sign In page in browser. 2. URL is shown is correct on login. 3. All contents are displayed properly. 4. Verify that screen is not going beyond display limit. | H2: test_SignIn_Page
A3: TC2 | B3: Functionality | C3: Sign In | D3: Launch Sign In Page | E3: Verify the UI/UX of JioSignage page. | F3: 1. Launch JioSignage Sign In Page : https://digitalsignage.jio.com/users/sign in . 2.Now observe the sign in page alignment and text. | G3: User should able to launch JioSignage in browser and all UI is user understandable & User experience interaction is simple and easily understandable. | H3: test_SignIn_Page_UIUX
A4: TC3 | B4: Functionality | C4: Sign In | D4: Launch Sign In Page | E4: Verify user able to see the JioSignage logo in JioSignage login page. | F4: 1. Launch JioSignage Sign In Page : https://digitalsignage.jio.com/users/sign in . 2.Now observe the sign in page alignment. | G4: JioSignage logo should available in top left. | H4: test_SignIn_Page_JioSignageLogo
A5: TC4 | B5: Functionality | C5: Sign In | D5: Launch Sign In Page | E5: Check user able to enter any text in Email address field. | F5: 1. Launch JioSignage Sign In Page : https://digitalsignage.jio.com/users/sign in . 2.Now enter any text in email address field and observe. | G5: User should able to enter the text and also able to edit. | H5: test_EmailTextbox
A6: TC5 | B6: Functionality | C6: Sign In | D6: Launch Sign In Page | E6: Check user able to enter the text in Password field. | F6: 1. Launch JioSignage Sign In Page : https://digitalsignage.jio.com/users/sign in . 2.Now enter any in password field and observe. | G6: User should able to enter the text and also able to edit. | H6: test_PasswordTextbox
A7: TC6 | B7: Functionality | C7: Sign In | D7: Launch Sign In Page | E7: Verify user is able to click password show icon in JioSignage login page. | F7: 1. Launch JioSignage Sign In Page : https://digitalsignage.jio.com/users/sign in . 2.Now enter any in password field and observe. 3Now click on eye icon from password field and observe the behaviour. 4.observe | G7: User should able to select the eye icon from password field. | H7: test_PasswordTextbox_showPasswordBtn
A8: TC7 | B8: Functionality | C8: Sign In | D8: Launch Sign In Page | E8: Verify user able to select the remember me option in JioSignage page. | F8: 1. Launch JioSignage Sign In Page : https://digitalsignage.jio.com/users/sign in . 2.Now enter any in password field and observe. 3.Now click on eye icon from password field and observe the behaviour. 4.Now select the remember me option and observe the behaviour. | G8: User should able to select the remember me option in JioSignage page. | H8: test_RememberMeOption
A9: TC8 | B9: Functionality | C9: Sign In | D9: Forgot Option | E9: Verify user able to create new password by using password forgot option. | F9: 1. Launch JioSignage Sign In Page : https://digitalsignage.jio.com/users/sign in . 2.Now enter your register email id and click on forget option>enter your email and click on submit>and check on your register mail and create new password. | G9: User should able to reset the password by clicking forget option and able to reset the password.
A10: TC9 | B10: Functionality | C10: Sign In | D10: Launch Sign In Page | E10: Verify user able to login using valid credentials in JioSignage login page. | F10: 1. Launch JioSignage Sign In Page : https://digitalsignage.jio.com/users/sign in . 2.Now enter your register email id in email id field. 3.Now enter the password in password field. 4.Click on get opt. 5.Now check your register mobile number or email. 6.Now click on submit OTP and observe the behaviour. | G10: User should able to login using valid credentials. | H10: test_LoginWithValidCredential
A11: TC10 | B11: Functionality | C11: Sign In | D11: OTP | E11: Verify user able to select the submit OTP in Enter OTP page. | F11: 1. Launch JioSignage Sign In Page : https://digitalsignage.jio.com/users/sign in . 2.Now enter your register email id in email id field. 3.Now enter the password in password field. 4.Click on get opt. 5.Now check your register mobile number or email. 6.Enter 6 digits OTP and click on submit OTP and observe the behaviour. | G11: User able to enter the OTP and able to login in JioSignage page
A12: TC11 | B12: Functionality | C12: Sign In | D12: OTP | E12: Verify user able to see & click on resend OTP in enter OTP page. | F12: 1. Launch JioSignage Sign In Page : https://digitalsignage.jio.com/users/sign in . 2.Now enter your register email id in email id field. 3.Now enter the password in password field. 4.Click on get opt. 5.Now check your register mobile number or email. 6.Enter 6 digits OTP and click on resend OTP and observe. | G12: User able to click resend OTP option in enter OTP page.
A13: TC12 | B13: Functionality | C13: Sign In | D13: OTP | E13: Verify user able to click back button to redirect previous page from OTP page. | F13: 1. Launch JioSignage Sign In Page : https://digitalsignage.jio.com/users/sign in . 2.Now enter your register email id in email id field. 3.Now enter the password in password field. 4.Click on get OTP. 5.Now check your register mobile number or email. 6.Enter 6 digits OTP and click on back button and observe. | G13: User should able to redirect to previous page . | H13: test_back_button_fromOTP_page
A14: TC13 | B14: Functionality | C14: Sign In | D14: OTP | E14: Verify able to regenerate OTP | F14: 1.Launch JioSignage Sign in Page: https://digitalsignage.jio.com/users/sign_in . 2.Enter valid email and password 3.Click on Get OTP 4.Enter the password received in Email after 6 mins. 5.Click on Regenerate on OTP Expired OSD. 6.Observe | G14: User should be able to regenerate OTP
A15: TC14 | B15: Functionality | C15: Profile | D15: Profile | E15: check user able to select the view profile option. | F15: Precondition: Register your email id and mobile number in JioSignage with help of existing SP user. 1.Enter URL in address bar JioSignage Sign In Page :https://digitalsignage.jio.com/users/sign in . 2.Now enter valid credentials and click on get opt. 3.Enter OTP and click on submit opt. 4.click on profile icon top right 1st option and observe the behaviour. | G15: It should redirect to profile page and user will see the User Name, Email Address, Phone number, Password. | H15: test_viewProfile
A16: TC15 | B16: Functionality | C16: Profile | D16: Update User Name | E16: check user able to update the user name. | F16: 1.Enter URL in address bar JioSignage Sign In Page :https://digitalsignage.jio.com/users/sign in . 2.Now enter valid credentials and click on get opt. 3.Enter OTP and click on submit opt. 4.click on profile icon top right 1st option>click on edit option in username>new user name>edit name>click on save option and observe the behaviour. | G16: user details has been successfully updated" pop up message should display on screen. | H16: test_verifyeditusername
A17: TC16 | B17: Functionality | C17: Profile | D17: Update User Name | E17: check user able to click "save" and "cancel "option" from user name OSD. | F17: 1.Enter URL in address bar JioSignage Sign In Page :https://digitalsignage.jio.com/users/sign in . 2.Now enter valid credentials and click on get opt. 3.Enter OTP and click on submit opt. 4.click on profile icon top right 1st option>click on edit option in username>edit name>click on save and cancel option and observe the behaviour. | G17: User should able to select the save and cancel option. | H17: test_editUserName_SAVE_CANCEL_BTN
A18: TC17 | B18: Functionality | C18: Profile | D18: Update User Name | E18: check user able to update the phone number. | F18: 1.Enter URL in address bar JioSignage Sign In Page :https://digitalsignage.jio.com/users/sign in . 2.Now enter valid credentials and click on get opt. 3.Enter OTP and click on submit opt. 4.click on profile icon top right 1st option>click on edit option in phone number>new phone number>edit number>click on save option and observe the behaviour. | G18: user details has been successfully updated" pop up message should display on screen. | H18: test_editphonenumber
A19: TC18 | B19: Functionality | C19: Profile | D19: Update User Name | E19: check user able to click "save" and "cancel "option" from new phone number OSD. | F19: 1.Enter URL in address bar JioSignage Sign In Page :https://digitalsignage.jio.com/users/sign in . 2.Now enter valid credentials and click on get opt. 3.Enter OTP and click on submit opt. 4.click on profile icon top right 1st option>click on edit option in phone number>edit phone number>click on save and cancel option and observe the behaviour. | G19: User should able to select the save and cancel option. | H19: test_editPhoneNumber_SAVE_CANCEL_BTN
A20: TC19 | B20: Functionality | C20: Profile | D20: Update User Name | E20: verify user able to close the new phone number OSD by clicking "X" | F20: 1.Enter URL in address bar JioSignage Sign In Page :https://digitalsignage.jio.com/users/sign in . 2.Now enter valid credentials and click on get opt. 3.Enter OTP and click on submit opt. 4.click on profile icon top right 1st option>click on edit option in phone number>edit phone number>click on "X" option and observe. | G20: User should able to select "X" option. | H20: test_editPhoneNumber_X_BTN
A21: TC20 | B21: Functionality | C21: Profile | D21: Update User Name | E21: check user able to update the password. | F21: 1.Enter URL in address bar JioSignage Sign In Page :https://digitalsignage.jio.com/users/sign in . 2.Now enter valid credentials and click on get opt. 3.Enter OTP and click on submit opt. 4.click on profile icon top right 1st option>click on edit option in password field>enter password on new password field>New password confirm field>click on save option and observe the behaviour. | G21: user details has been successfully updated" toast message should display on screen and user gets logout.
A22: TC21 | B22: Functionality | C22: Profile | D22: Update User Name | E22: Check user able to update the password with two different password in two different field and observe. | F22: 1.Enter URL in address bar JioSignage Sign In Page :https://digitalsignage.jio.com/users/sign in . 2.Now enter valid credentials and click on get opt. 3.Enter OTP and click on submit opt. 4.click on profile icon top right 1st option>click on edit option in password field>enter password on new password field>In New password confirm field enter another password which is different for new password field>click on save option and observe the behaviour. | G22: It should lead error message on display "Doesn't match confirmation". | H22: test_twoDifferentPassword_alert
A23: TC22 | B23: Functionality | C23: Profile | D23: Update User Name | E23: check user able to click "save" and "cancel "option" from new password OSD. | F23: 1.Enter URL in address bar JioSignage Sign In Page :https://digitalsignage.jio.com/users/sign in . 2.Now enter valid credentials and click on get opt. 3.Enter OTP and click on submit opt. 4.click on profile icon top right 1st option>click on edit option in password field>enter password on new password field>New password confirm field>click on save and cancel option and observe. | G23: User should able to select the save and cancel option.
A24: TC23 | B24: Functionality | C24: Profile | D24: Update User Name | E24: verify user able to close the new password OSD by clicking "X" | F24: 1.Enter URL in address bar JioSignage Sign In Page :https://digitalsignage.jio.com/users/sign in . 2.Now enter valid credentials and click on get opt. 3.Enter OTP and click on submit opt. 4.click on profile icon top right 1st option>click on edit option in password>edit password>click on "X" option and observe. | G24: User should able to select "X" option. | H24: test_editPassword_X_BTN
A25: TC24 | B25: Functionality | C25: Profile | D25: Service Plan | E25: Verify user able to select the view service plan from profile. | F25: 1.Enter URL in address bar JioSignage Sign In Page :https://digitalsignage.jio.com/users/sign in . 2.Now enter valid credentials and click on get opt. 3.Enter OTP and click on submit opt. 4.click on profile icon top right 1st option>click on view service plan and observe the behaviour. | G25: It should redirect to service plan page it should display Plan Name Demo. Server Usage. Number of Display. | H25: test_ViewServicePlan
A26: TC25 | B26: Functionality | C26: Profile | D26: Help | E26: Verify user able to select the help option from profile icon. | F26: 1.Enter URL in address bar JioSignage Sign In Page :https://digitalsignage.jio.com/users/sign in . 2.Now enter valid credentials and click on get opt. 3.Enter OTP and click on submit opt. 4.click on profile icon top right 1st option>click on help option and observe the behaviour. | G26: It should redirect to help line page. | H26: test_Help_Page
A27: TC26 | B27: Functionality | C27: Profile | D27: Logout | E27: Verify user able to select the logout option from profile icon. | F27: 1.Enter URL in address bar JioSignage Sign In Page :https://digitalsignage.jio.com/users/sign in . 2.Now enter valid credentials and click on get opt. 3.Enter OTP and click on submit opt. 4.click on profile icon top right 1st option>click on logout >click on option and observe the behaviour. | G27: User should logout the JioSignage page by clicking logout. | H27: test_LogoutOption

Sheet Dashboard
A1: Sr. No | B1: Test Type | C1: Functionality Name | D1: Sub Functionality | E1: Test Objective | F1: Test Steps | G1: Expected Behavior | H1: Automation TC Name | I1: Result | J1: Comment
A2: TC1 | B2: Functionality | C2: Dashboard | D2: Launch dashboard. | E2: Verify able to see the JioSignage welcome page with JioSignage logo. | F2: 1.Enter URL in address bar JioSignage Sign In Page :https://digitalsignage.jio.com/users/sign in . 2.Now enter valid credentials and click on get OTP . 3.Enter OTP and click on submit OTP . 4.Now observe the JioSignage logo in left top. | G2: User should able to see the JioSignage logo or icon in left top corner after successful login using valid credentials. | H2: test_verifySignageWelcomePage
A3: TC2 | B3: Functionality | C3: Dashboard | D3: Launch dashboard. | E3: Verify able to see the welcome page message on top left. | F3: 1.Enter URL in address bar JioSignage Sign In Page :https://digitalsignage.jio.com/users/sign in . 2.Now enter valid credentials and click on get OTP . 3.Enter OTP and click on submit OTP . 4.Observe the welcome message. | G3: User should able to see the welcome message with "Track, Analyse and report all content displayed on the display". | H3: test_verifyWelcomeHeading
A4: TC3 | B4: Functionality | C4: Dashboard | D4: JioSignage Logo | E4: Check the behavior when click on JioSignage logo | F4: 1.Enter URL in address bar JioSignage Sign In Page :https://digitalsignage.jio.com/users/sign in . 2.Now enter valid credentials and click on get OTP . 3.Enter OTP and click on submit OTP . 4.Observe the home screen > go to other menu option screen e.g. select delivery management > observe the delivery management screen. 5.Click on JioSignage logo from the top left of the screen. 6.Observe the behavior. | G4: User should be redirected to the dashboard screen from any other option screen when click on the JioSignage logo. | H4: test_signageLogo
A5: TC4 | B5: Functionality | C5: Dashboard | D5: Display License | E5: Verify user able to see the total display license details count. | F5: 1.Enter URL in address bar JioSignage Sign In Page :https://digitalsignage.jio.com/users/sign in . 2.Now enter valid credentials and click on get OTP . 3.Enter OTP and click on submit OTP . 4.Observe the display license count. | G5: User should able to see the total display count details in display license box. | H5: test_verifyDisplayCount
A6: TC5 | B6: Functionality | C6: Dashboard | D6: Display License | E6: Verify used/remain storage details in display license feature. | F6: 1.Enter URL in address bar JioSignage Sign In Page :https://digitalsignage.jio.com/users/sign in . 2.Now enter valid credentials and click on get OTP . 3.Enter OTP and click on submit OTP . 4.Observe the Used/Remaining storage status on display license box. | G6: User should able to see, how many license displays are used and how many are remaining clearly. | H6: test_verifyUsedDisplayCount
A7: TC6 | B7: Functionality | C7: Dashboard | D7: Display License | E7: Verify Total display license details and used/remain details in display license feature are correct | F7: 1.Enter URL in address bar JioSignage Sign In Page :https://digitalsignage.jio.com/users/sign in . 2.Now enter valid credentials and click on get OTP . 3.Enter OTP and click on submit OTP . 4.Verify Total display license details & Used/Remaining details on display license box are correct. | G7: Total , Used , Remaining display count should be as per plan and as per usage. | H7: test_verifyUsedRemainingLicense
A8: TC7 | B8: Functionality | C8: Dashboard | D8: Storage | E8: Verify user able to see the total storage details on storage box in dashboard page. | F8: 1.Enter URL in address bar JioSignage Sign In Page :https://digitalsignage.jio.com/users/sign in . 2.Now enter valid credentials and click on get OTP . 3.Enter OTP and click on submit OTP . 4.Now observe the storage box total storage. | G8: User should able to see the total storage details like circle shape with 2048mb. | H8: test_verifyUsedRemainStorage
A9: TC8 | B9: Functionality | C9: Dashboard | D9: Storage | E9: Verify storage details on storage box in dashboard page are correct. | F9: 1.Enter URL in address bar JioSignage Sign In Page :https://digitalsignage.jio.com/users/sign in . 2.Now enter valid credentials and click on get OTP . 3.Enter OTP and click on submit OTP . 4. Verify Total storage , remaining storage details are correct | G9: Total , Used , Remaining storage should be as per plan and as per usage , should show correct details | H9: test_verifyUsedStorage
A10: TC9 | B10: Functionality | C10: Dashboard | D10: Storage | E10: Check user able to see the remaining storage details on storage box in dashboard page. | F10: 1.Enter URL in address bar JioSignage Sign In Page :https://digitalsignage.jio.com/users/sign in . 2.Now enter valid credentials and click on get OTP . 3.Enter OTP and click on submit OTP . 4.Now place the pointer on remaining indication color and observe the behavior. | G10: User should able to see the remaining details with MB when we place on remaining storage circle. | H10: test_getStorageDataFromCanvas
A11: TC10 | B11: Functionality | C11: Dashboard | D11: Storage | E11: Check user able to see the service plan page when we click on used storage and observe. | F11: 1.Enter URL in address bar JioSignage Sign In Page :https://digitalsignage.jio.com/users/sign in . 2.Now enter valid credentials and click on get OTP . 3.Enter OTP and click on submit OTP . 4.Now click on used storage and observe. | G11: After clicking on used MB data its redirecting to service plan page. | H11: test_verifyStorageLink
A12: TC11 | B12: Functionality | C12: Dashboard | D12: Service Plan | E12: Verify server usage details on service plan page. | F12: 1.Enter URL in address bar JioSignage Sign In Page :https://digitalsignage.jio.com/users/sign in . 2.Now enter valid credentials and click on get OTP . 3.Enter OTP and click on submit OTP . 4.Now click on used storage and observe the server usage and number of display details with used and remaining details. | G12: It should show the service usage and number of display play details with proper used and remaining data in detailed in service plan page. | H12: test_verify_serverUsage
A13: TC12 | B13: Functionality | C13: Dashboard | D13: Media Uploaded | E13: Check user able to see the media uploaded details box in dashboard page. | F13: 1.Enter URL in address bar JioSignage Sign In Page :https://digitalsignage.jio.com/users/sign in . 2.Now enter valid credentials and click on get OTP . 3.Enter OTP and click on submit OTP . 4.Now observe the media uploaded feature box. | G13: User should able to see the media uploaded box in 2nd row 1st column | H13: test_verify_media_uploaded_location
... A41: TC41 | B41: Functionality | C41: Dashboard | D41: Display | E41: Check user able to see the tag wise display box in dashboard page. | F41: 1.Enter URL in address bar JioSignage Sign In Page :https://digitalsignage.jio.com/users/sign in . 2.Now enter valid credentials and click on get OTP . 3.Enter OTP and click on submit OTP . 4.Now observe the tag wise display feature box. | G41: User should able to see the tag wise box in 3rd row 2nd. | H41: test_TagWIseDisplay_location
A42: TC42 | B42: Functionality | C42: Dashboard | D42: Display | E42: Verify user able to see the tool tip when place mouse on bar chat. | F42: 1.Enter URL in address bar JioSignage Sign In Page :https://digitalsignage.jio.com/users/sign in . 2.Now enter valid credentials and click on get OTP . 3.Enter OTP and click on submit OTP . 4.Now observe the tag wise display feature box. 5.Now observe the status of the tag wise display details. 6.Now place on bar chat and observe the behavior. | G42: It should show tool tip with count.
A43: TC43 | B43: Functionality | C43: Dashboard | D43: Display | E43: Check user able to see the state wise display details box in dashboard page. | F43: 1.Enter URL in address bar JioSignage Sign In Page :https://digitalsignage.jio.com/users/sign in . 2.Now enter valid credentials and click on get OTP . 3.Enter OTP and click on submit OTP . 4.Now observe the state wise display details box feature box. | G43: User should able to see the display status box in 4th row 1st, | H43: test_stateWIseDisplay_location
A44: TC44 | B44: Functionality | C44: Dashboard | D44: Display | E44: Verify user able to identify online and offline status. | F44: 1.Enter URL in address bar JioSignage Sign In Page :https://digitalsignage.jio.com/users/sign in . 2.Now enter valid credentials and click on get OTP . 3.Enter OTP and click on submit OTP . 4.Now observe the city wise display details box. 5. Check the online & offline graph details. | G44: It should show color coating for identification like for online>light green and for offline blue.
A45: TC45 | B45: Functionality | C45: Dashboard | D45: Launch dashboard. | E45: Verify user able to switch head user account to base account. | F45: 1.Enter URL in address bar JioSignage Sign In Page :https://digitalsignage.jio.com/users/sign in . 2.Now enter valid credentials and click on get OTP . 3.Enter OTP and click on submit OTP . 4.click on head user top right 2nd option. 5.Click on switch to base account>now click on search drop down and select any base account>press ok and observe the behavior. | G45: User should able to change the head user account to base account. | H45: test_verifyChangeBaseAccount
A46: TC46 | B46: Functionality | C46: Dashboard | D46: Launch dashboard. | E46: Verify ok and cancel button is working on select on base account page. | F46: 1.Enter URL in address bar JioSignage Sign In Page :https://digitalsignage.jio.com/users/sign in . 2.Now enter valid credentials and click on get OTP . 3.Enter OTP and click on submit OTP . 4.click on head user top right 2nd option. 5.Click on switch to base account>now click on search drop down and select any base account>press ok and cancel button and observe the behavior. | G46: "Ok" and "cancel" button should work after selecting any base item from the list. | H46: test_verifyOkCancelButtonOnChangeAccount
A47: TC47 | B47: Functionality | C47: Dashboard | D47: Profile | E47: Check user able to select the view profile OTP ion. | F47: 1.Enter URL in address bar JioSignage Sign In Page :https://digitalsignage.jio.com/users/sign in . 2.Now enter valid credentials and click on get OTP . 3.Enter OTP and click on submit OTP . 4.click on profile icon top right 1st OTP ion and observe the behaviour. | G47: It should redirect to profile page and user will see the User Name, Email Address, Phone number, Password. | H47: test_verifyProfileOptions
A48: TC48 | B48: Functionality | C48: Dashboard | D48: Profile | E48: Check user able to click "save" and "cancel" option" from user name OSD. | F48: 1.Enter URL in address bar JioSignage Sign In Page :https://digitalsignage.jio.com/users/sign in . 2.Now enter valid credentials and click on get OTP . 3.Enter OTP and click on submit OTP . 4.click on profile icon top right 1st option>click on edit option in username>edit name>click on save and cancel option and observe the behavior. | G48: User should able to select the save and cancel option. | H48: test_verifySaveCancelOptionOnChangeName
A49: TC49 | B49: Functionality | C49: Dashboard | D49: Profile | E49: Check user able to click "save" and "cancel" option" from new phone number OSD. | F49: 1.Enter URL in address bar JioSignage Sign In Page :https://digitalsignage.jio.com/users/sign in . 2.Now enter valid credentials and click on get OTP . 3.Enter OTP and click on submit OTP . 4.click on profile icon top right 1st option>click on edit option in phone number>edit phone number>click on save and cancel option and observe the behavior. | G49: User should able to select the save and cancel option. | H49: test_verifySaveCancelOptionOnChangePhone
A50: TC50 | B50: Functionality | C50: Dashboard | D50: Profile | E50: Verify user able to close the new phone number osd by clicking "X" | F50: 1.Enter URL in address bar JioSignage Sign In Page :https://digitalsignage.jio.com/users/sign in . 2.Now enter valid credentials and click on get OTP . 3.Enter OTP and click on submit OTP . 4.click on profile icon top right 1st option>click on edit option in phone number>edit phone number>click on "X" option and observe. | G50: User should able to select "X" option. | H50: test_verifyCrossOnEditPhoneNum
A51: TC51 | B51: Functionality | C51: Dashboard | D51: Profile | E51: Check user able to update the password with two different password in two different field and observe. | F51: 1.Enter URL in address bar JioSignage Sign In Page :https://digitalsignage.jio.com/users/sign in . 2.Now enter valid credentials and click on get OTP . 3.Enter OTP and click on submit OTP . 4.click on profile icon top right 1st option>click on edit OTP ion in password field>enter password on new password field>In New password confirm field enter another password which is different for new password field>click on save option and observe the behavior. | G51: It should lead error message on display "Doesn't match confirmation". | H51: test_verifyUpdateMismatchPas
A52: TC52 | B52: Functionality | C52: Dashboard | D52: Profile | E52: Verify user able to close the new phone number osd by clicking "X" | F52: 1.Enter URL in address bar JioSignage Sign In Page :https://digitalsignage.jio.com/users/sign in . 2.Now enter valid credentials and click on get OTP . 3.Enter OTP and click on submit OTP . 4.click on profile icon top right 1st option>click on edit option in password>edit password>click on "X" option and observe. | G52: User should able to select "X" option. | H52: test_verifyCrossOnEditPassword
A53: TC53 | B53: Functionality | C53: Dashboard | D53: Profile | E53: Verify user able to select the view service plan from profile. | F53: 1.Enter URL in address bar JioSignage Sign In Page :https://digitalsignage.jio.com/users/sign in . 2.Now enter valid credentials and click on get OTP . 3.Enter OTP and click on submit OTP . 4.click on profile icon top right 1st option>click on view service plan and observe the behavior. | G53: It should redirect to service plan page it should display Plan Name Demo. Server Usage. Number of Display. | H53: test_verifyServicePlan
A54: TC54 | B54: Functionality | C54: Dashboard | D54: Profile | E54: Verify user able to select the help OTP ion from profile icon. | F54: 1.Enter URL in address bar JioSignage Sign In Page :https://digitalsignage.jio.com/users/sign in . 2.Now enter valid credentials and click on get OTP . 3.Enter OTP and click on submit OTP . 4.click on profile icon top right 1st OTP ion>click on help OTP ion and observe the behaviour. | G54: It should redirect to help line page. | H54: test_JioHelpOnProfile
A55: TC55 | B55: Functionality | C55: Dashboard | D55: Profile | E55: Verify user able to select the logout option from profile icon. | F55: 1.Enter URL in address bar JioSignage Sign In Page :https://digitalsignage.jio.com/users/sign in . 2.Now enter valid credentials and click on get OTP . 3.Enter OTP and click on submit OTP . 4.click on profile icon top right 1st option>click on logout >click on option and observe the behavior. | G55: User should logout the JioSignage page by clicking logout. | H55: test_logout
A56: TC56 | B56: Functionality | C56: Dashboard | D56: Profile | E56: Click on FAQ and observe the behavior. | F56: 1.Enter URL in address bar JioSignage Sign In Page :https://digitalsignage.jio.com/users/sign in . 2.Now enter valid credentials and click on get OTP . 3.Enter OTP and click on submit OTP . 4.Now scroll down select FAQ option which is available in down side right fourth option and observe the behavior. | G56: It should redirect to frequently asked question page with options listed below. Search bar. JioSignage Display Trouble Shooting Content Proof of Play. | H56: test_verifyFAQ
... A59: TC59 | B59: Functionality | C59: Dashboard | D59: Launch dashboard. | E59: Click on Terms and condition option and observe the behavior. | F59: 1.Enter URL in address bar JioSignage Sign In Page :https://digitalsignage.jio.com/users/sign in . 2.Now enter valid credentials and click on get OTP . 3.Enter OTP and click on submit OTP . 4.Now scroll down select Privacy policy option which is available in down side right first option and observe the behavior. | G59: Terms and condition page should appears in display. | H59: test_verifyTermsAndConditions
A60: TC60 | B60: Functionality | C60: Dashboard | D60: Location wise display | E60: Check user able to see the Location wise display details box in dashboard page. | F60: 1.Enter URL in address bar JioSignage Sign In Page :https://digitalsignage.jio.com/users/sign in . 2.Now enter valid credentials and click on get OTP . 3.Enter OTP and click on submit OTP . 4.Now observe the Location wise display box feature box. | G60: User should able to see the display status box in 7th row in dashboard page.
A61: TC61 | B61: Functionality | C61: Dashboard | D61: Location wise display | E61: Verify user able to zoom in and zoom out using + and - symbols which is available in left side top on location wise display section. | F61: 1.Enter URL in address bar JioSignage Sign In Page :https://digitalsignage.jio.com/users/sign in . 2.Now enter valid credentials and click on get OTP . 3.Enter OTP and click on submit OTP . 4.Now observe the Location wise display box feature box. 5.Now click on + and - icon and | G61: Zoom in (+) and zoon out(-) functional should work as per RIL requirement.
A62: TC62 | B62: Functionality | C62: Dashboard | D62: Location wise display | E62: Verify user able to zoom in and zoom out using two finger pinch in /out on map. | F62: 1.Enter URL in address bar JioSignage Sign In Page :https://digitalsignage.jio.com/users/sign in . 2.Now enter valid credentials and click on get OTP . 3.Enter OTP and click on submit OTP . 4.Now observe the Location wise display box feature box > observe the map. 5.check two finger zoom in/out using trackpad. | G62: User should able to zoom in/out using to finger pinch on/out by trackpad of laptop.
A63: TC63 | B63: Functionality | C63: Dashboard | D63: Location wise display | E63: Verify user able to see the city wise display locations on map. | F63: 1.Enter URL in address bar JioSignage Sign In Page :https://digitalsignage.jio.com/users/sign in . 2.Now enter valid credentials and click on get OTP . 3.Enter OTP and click on submit OTP . 4.Now observe the Location wise display box feature box. 5.Now click on + and - icon and 6.Now observe the location tags in map. | G63: User able to see the display location in location wise display section.
A64: TC64 | B64: Functionality | C64: Dashboard | D64: Location wise display | E64: Verify user able to see the created locations display is reflecting location wise display. | F64: 1.Enter URL in address bar JioSignage Sign In Page :https://digitalsignage.jio.com/users/sign in . 2.Now enter valid credentials and click on get OTP . 3.Enter OTP and click on submit OTP . 4.Now observe the Location wise display box feature box. 5.Now click on content>displays>click on + icon (add new display)>Now add details in respective sections and click add . 6.Login into the display at client side with same credentials and make the client display Online. 7.Now go to Dashboard and observe the location as updated in location wise display section. | G64: Newly added location details should reflect and location indication should show in location wise display.
A65: TC65 | B65: Functionality | C65: Dashboard | D65: Location wise display | E65: Verify user able to see the display status in location wise display page. | F65: 1.Enter URL in address bar JioSignage Sign In Page :https://digitalsignage.jio.com/users/sign in . 2.Now enter valid credentials and click on get OTP . 3.Enter OTP and click on submit OTP . 4.Now observe the Location wise display box feature box. 5.Now Place the mouse on location indication and observe. | G65: Correct Display details should display when we place mouse pointer lo location indication.
A66: TC66 | B66: Functionality | C66: Dashboard | D66: Cable Status | E66: Verify cable status showing correct cable status | F66: 1.Enter URL in address bar JioSignage Sign In Page :https://digitalsignage.jio.com/users/sign in . 2.Now enter valid credentials and click on get OTP . 3.Enter OTP and click on submit OTP . 4.Now observe the cable status box feature box. 5.Now observe the cable status. | G66: Cable status should show correct disconnected cable status , as per Delivery Management page | H66: test_Displaydisconnected_dashboard
A67: TC67 | B67: Functionality | C67: Dashboard | D67: Tag wise display | E67: Verify Tag wise display details are correct | F67: 1.Enter URL in address bar JioSignage Sign In Page :https://digitalsignage.jio.com/users/sign in . 2.Now enter valid credentials and click on get OTP . 3.Enter OTP and click on submit OTP . 4.Now observe the tag wise display feature box. 5.click on any chat bar from the tag wise box and observe display details>now navigate to display and observe. | G67: Tag wise display details should match with actual details in the display page. | H67: test_verifytagwisecount
A68: TC69 | B68: Functionality | C68: Dashboard | D68: Location wise display | E68: Verify user able to see the Online display details , when filter ONLINE in location wise display page. | F68: 1.Enter URL in address bar JioSignage Sign In Page :https://digitalsignage.jio.com/users/sign in . 2.Now enter valid credentials and click on get OTP . 3.Enter OTP and click on submit OTP . 4.Now observe the Location wise display box feature box. 5. click on all drop down and select online and observe. | G68: User should see the correct online display details when we apply filter to online only"
A69: TC70 | B69: Functionality | C69: Dashboard | D69: Location wise display | E69: Verify user able to see the Offline display details , when filter OFFLINE in location wise display page. | F69: 1.Enter URL in address bar JioSignage Sign In Page :https://digitalsignage.jio.com/users/sign in . 2.Now enter valid credentials and click on get OTP . 3.Enter OTP and click on submit OTP . 4.Now observe the Location wise display box feature box. 5. click on all drop down and select offline and observe. | G69: User should see the correct offline display details when we apply filter to offline only"
...

Sheet Materials
A1: Sr. No | B1: Test Type | C1: Functionality Name | D1: Sub Functionality | E1: Test Objective | F1: Test Steps | G1: Expected Behaviour | H1: Automation test case name | I1: Result | J1: Comment
A2: TC1 | B2: Functionality | C2: Media | D2: Landing Page | E2: Verify Media table should be empty when no Media are uploaded | F2: 1. Launch JioSignage Sign In Page : https://digitalsignage.jio.com/users/sign_in . 2. Login with valid credentials. 3.Click content management > Media 4. Observe the Table | G2: 1. Table should be empty 2. No data available in the table text should be written 3. Showing 0 to 0 of 0 entries text should be written at the bottom of the table | H2: test_materialPage_noDataUploaded
A3: TC2 | B3: Functionality | C3: Media | D3: Add New Material | E3: Verify add new Media functionality | F3: 1. Launch JioSignage Sign In Page : https://digitalsignage.jio.com/users/sign_in . 2. Login with valid credentials. 3.Click content management > media 4.Click Add new media (+) button that present on right side. 5. Observe | G3: 1. Upload Media OSD should open 2. Verify supported file formats , Max size, max file limits and close button are present | H3: test_addNewMaterial_OSD
A4: TC3 | B4: Functionality | C4: Media | D4: Browse | E4: Verify browse functionality | F4: 1.Launch JioSignage Sign In Page : https://digitalsignage.jio.com/users/sign_in . 2.Login with valid credentials. 3.Click content management > media 4. Click Add new media (+) button that present on right side. 5.On Upload Media OSD click on browse 6.Select a file -> Click on Open 7.Observe | G4: 1. User should be able to browse files from system 2. The Selected file should be observed after the file is selected | H4: test_addNewMaterial_clickOnBrowse
A5: TC4 | B5: Functionality | C5: Media | D5: Upload Functionality | E5: Verify user is able to Upload JPEG File Type as a media | F5: 1. Launch JioSignage Sign In Page : https://digitalsignage.jio.com/users/sign_in . 2. Login with valid credentials. 3.Click content management > media 4.Click Add new media (+) button that present on right side. 5. Click on "Drag and Drop files here or click to browse". 6. select the Jpeg file or perform drag and drop operation . 7. Click on open. 8. Click on Upload | G5: 1. Media uploaded successfully message should be observed. 2.User should be able to upload JPEG File Type as a material 3. The uploaded media should be observed in Material Table | H5: test_addNewMaterial_JPEG
A6: TC5 | B6: Functionality | C6: Media | D6: Upload Functionality | E6: Verify user is able to Upload PNG File Type as a media | F6: 1. Launch JioSignage Sign In Page : https://digitalsignage.jio.com/users/sign_in . 2. Login with valid credential. 3.Click content management > media 4.Click Add new media (+) button that present on right side. 5. Click on "Drag and Drop files here or click to browse". 6. select the file or perform drag and drop operation. 7. Click on open. 8. Click on Upload | G6: 1. Material uploaded successfully notification should be observed 2.User should be able to upload PNG Image File Type as a material 3. The uploaded material should be observed in Material Table | H6: test_addNewMaterial_PNG
A7: TC6 | B7: Functionality | C7: Media | D7: Upload Functionality | E7: Verify user is able to upload GIF File Type as a media | F7: 1. Launch JioSignage Sign In Page : https://digitalsignage.jio.com/users/sign_in . 2. Login with valid credentials 3.Click content management > media 4.Click Add new media (+) button that present on right side. 5. Click on "Drag and Drop files here or click to browse". 6. select the file or perform drag and drop operation. 7. Click on open. 8. Click on Upload | G7: 1. Media uploaded successfully notification should be observed 2.User should be able to upload GIF Image File Type as a material 3. The uploaded material should be observed in Material Table | H7: test_addNewMaterial_GIF
A8: TC7 | B8: Functionality | C8: Media | D8: Upload Functionality | E8: Verify user is able to upload JFIF File Type as a media | F8: 1. Launch JioSignage Sign In Page : https://digitalsignage.jio.com/users/sign_in . 2. Login with valid credentials 3.Click content > material 4.Click Add new media (+) button that present on right side. 5. Click on "Drag and Drop files here or click to browse". 6. select the file or perform drag and drop operation. 7. Click on open. 8. Click on Upload | G8: 1. Media uploaded successfully notification should be observed 2.User should be able to upload JFIF Image File Type as a material | H8: test_addNewMaterial_JFIF
A9: TC8 | B9: Functionality | C9: Media | D9: Upload Functionality | E9: Verify user is able to upload MP4 File Type as a media | F9: 1. Launch JioSignage Sign In Page : https://digitalsignage.jio.com/users/sign_in . 2. Login with valid credentials. 3.Click content management > media 4.Click + icon on to right side. 5. Click on "Drag and Drop files here or click to browse". 6. select the file or perform drag and drop operation. 7. Click on open. 8. Click on Upload | G9: 1. Media uploaded successfully notification should be observed 2.User should be able to upload MP4 File Type as a material 3. The uploaded material should be observed in Material Table | H9: test_addNewMaterial_MP4
A10: TC9 | B10: Functionality | C10: Media | D10: Upload Functionality | E10: Verify user is able to upload MOV File Type as a media | F10: 1. Launch JioSignage Sign In Page : https://digitalsignage.jio.com/users/sign_in . 2. Login with valid credentials. 3.Click content management > media 4.Click Add new media (+) button that present on right side. 5. Click on "Drag and Drop files here or click to browse". 6. select the file or perform drag and drop operation. 7. Click on open. 8. Click on Upload | G10: 1. Media uploaded successfully notification should be observed 2.User should be able to upload MOV File Type as a material 3. The uploaded material should be observed in Material Table | H10: test_addNewMaterial_MOV
A11: TC10 | B11: Functionality | C11: Media | D11: Upload Functionality | E11: Verify user is able to upload Webm File Type as a media | F11: 1. Launch JioSignage Sign In Page : https://digitalsignage.jio.com/users/sign_in . 2. Login with valid credentials 3.Click content management > media 4.Click Add new media (+) button that present on right side. 5. Click on "Drag and Drop files here or click to browse". 6. select the file or perform drag and drop operation. 7. Click on open. 8. Click on Upload | G11: 1. Media uploaded successfully notification should be observed 2.User should be able to upload Webm File Type as a media 3. The uploaded material should be observed in Media Table | H11: test_addNewMaterial_Webm
A12: TC11 | B12: Functionality | C12: Media | D12: Upload Functionality | E12: Verify user is able to upload MP3 File Type as a media | F12: 1. Launch JioSignage Sign In Page : https://digitalsignage.jio.com/users/sign_in . 2. Login with valid credentials. 3.Click content management > media 4.Click + icon on to right side. 5. Click on "Drag and Drop files here or click to browse". 6. select the file or perform drag and drop operation. 7. Click on open. 8. Click on Upload | G12: 1. Media uploaded successfully notification should be observed 2.User should be able to upload MP3 File Type as a media 3. The uploaded media should be observed in Media Table | H12: test_addNewMaterial_MP3
A13: TC12 | B13: Functionality | C13: Media | D13: Upload Functionality | E13: Verify user is able to upload Ogg Vorbis File Type as a media | F13: 1. Launch JioSignage Sign In Page : https://digitalsignage.jio.com/users/sign_in . 2. Login with valid credential 3.Click content management > media 4.Click Add new media (+) button that present on right side. 5. Click on "Drag and Drop files here or click to browse". 6. select the file or perform drag and drop operation. 7. Click on open. 8. Click on Upload | G13: 1. Media uploaded successfully notification should be observed 2.User should be able to upload Ogg Vorbis File Type as a media 3. The uploaded media should be observed in Media Table | H13: test_addNewMaterial_OGG
... A70: TC69 | B70: Functionality | C70: Material | D70: Arrow button functionality | E70: Verify left arrow (<) on bottom right corner on Materials | F70: 1. Launch JioSignage Sign In Page : https://digitalsignage.jio.com/users/sign_in . 2. Login with valid credentials. 3. Click content management> Media> upload Material 4. Click (<) arrow on bottom right corner. | G70: User should be able to see the previous set of entries by clicking on < | H70: test_verifyPreviousOptionOnMaterial
A71: TC70 | B71: Functionality | C71: Media | D71: Upload Functionality | E71: Verify user will get a warning message when uploading a file while storage is full | F71: Pre-Condition : Storage should be Full Steps : 1. Launch JioSignage Sign In Page : https://digitalsignage.jio.com/users/sign_in . 2. Login with valid credentials. 3. Click content management > Media 4. Click on Add new media 5. Click on "Drag and drop file here or click to browse" 6. Select Files according your choice 7. Click on Open 8. Click on upload | G71: User should get a warning message like "File is too big, max file size allowed is remaining storage". Also File upload should not happen.
A72: TC71 | B72: Functionality | C72: Media | D72: Shared functionality | E72: Verify user able to create Shared folder through Add folder option | F72: Steps : 1. Launch JioSignage Sign In Page : https://digitalsignage.jio.com/users/sign_in . 2. Login with valid credentials. 3. Click content management > Media 4. Click on Add folder button 5. Enter any name 6. Select the Shared checkbox 7. Click on Add | G72: User should get the message like "Folder has been successfully added" . Verify name of the folder in folder list.
A73: TC72 | B73: Functionality | C73: Shared Folder | D73: Upload Media | E73: Verify user able to upload media in shared folder that created through Add folder option | F73: Steps : 1. Launch JioSignage Sign In Page : https://digitalsignage.jio.com/users/sign_in . 2. Login with valid credentials. 3. Click content management > Media 4. Click on Add Folder button 5. Enter any name 6. Select the Shared checkbox 7. Click on Add 8. Click on Add Media(+) option 9. Click on "Drag and drop files here or click to browse" 10. Select required files and click on open 11. Click on upload | G73: User should able to upload media in the share folder that created through Add folder option
A74: TC73 | B74: Functionality | C74: Shared Folder | D74: Delete Media | E74: Verify user able to delete the files from shared folder that created through Add Folder option | F74: Steps : 1. Launch JioSignage Sign In Page : https://digitalsignage.jio.com/users/sign_in . 2. Login with valid credentials. 3. Click content management > Media 4. Click on Add media button(+) 5. Enter any name 6. Select the Shared checkbox 7. Click on Add 8. Add some file in that folder 9. Click on the checkbox for required media 10. Click on 3 dot 11. Click on Move to trash 12. Click on Ok | G74: User should able to delete the files from Shared folder that created through Add folder option
A75: TC74 | B75: Functionality | C75: Shared Folder | D75: Move Media | E75: Verify user able to move the files from shared folder to other folder that created through Add Folder option | F75: Steps : 1. Launch JioSignage Sign In Page : https://digitalsignage.jio.com/users/sign_in . 2. Login with valid credentials. 3. Click content management > Media 4. Click on Add Folder button 5. Enter any name 6. Select the Shared checkbox 7. Click on Add 8. Add some file in that folder 9. Click on the checkbox for required media 10. Click on 3 dot 11. Click on Move material 12. Click on Search and select the folder name 13. Click on Move | G75: User should able to move the media files from Shared folder to other folder
A76: TC75 | B76: Functionality | C76: Shared Folder | D76: Copy to Shared | E76: Verify user able to copy the files to Shared folder through "Copy to Shared folder" option | F76: Steps : 1. Launch JioSignage Sign In Page : https://digitalsignage.jio.com/users/sign_in . 2. Login with valid credentials. 3. Click content management > Media 4. Click on Add media button 5. Enter any name 6. Select the Shared checkbox 7. Click on Add 8. Add some file in that folder 9. Click on the checkbox for required media 10. Click on 3 dot 11. Click on Copy to Shared 12. Click on Ok | G76: User should able to copy the media files to Shared folder directly
A77: TC76 | B77: Functionality | C77: Shared Folder | D77: Create Playlist | E77: Verify user able to create new playlist using Shared folder files that created through Add Folder option | F77: Steps : 1. Launch JioSignage Sign In Page : https://digitalsignage.jio.com/users/sign_in . 2. Login with valid credentials. 3. Click content management > Media 4. Click on Add media button 5. Enter any name 6. Select the Shared checkbox 7. Click on Add 8. Add some file in that folder 9. Click on the checkboxes for required media 10. Click on 3 dot 11. Click on "Create playlist" 12. Select the radio button "New playlist" 13. Enter any playlist name 14. Set Image Default duration in sec 15. Click On Add | G77: User should able to create new playlist using shared folder media files
A78: TC77 | B78: Functionality | C78: Shared Folder | D78: Add Media to Existing Playlist | E78: Verify user able to add the shared folder files in Existing Playlist through "Create Playlist" option | F78: Steps : 1. Launch JioSignage Sign In Page : https://digitalsignage.jio.com/users/sign_in . 2. Login with valid credentials. 3. Click content management > Media 4. Click on Add media button 5. Enter any name 6. Select the Shared checkbox 7. Click on Add 8. Add some file in that folder 9. Click on the checkboxes for required media 10. Click on 3 dot 11. Click on "Create playlist" 12. Select the radio button "Existing playlist" 13. Select the Existing folder name 14. Set Image Default duration in sec 15. Click on Add | G78: User should able to add the shared folder files in existing playlist through "Create Playlist" option
A79: TC78 | B79: Functionality | C79: Media | D79: Move Media | E79: Verify user is able to move media file | F79: 1. Launch JioSignage Sign In Page : https://digitalsignage.jio.com/users/sign_in . 2. Login with valid credentials. 3.Click content management > media 4.Select any existing media(image) file. 5. Go to 3 dot button menu and select Move Media option. 6. Select required folder option and click Move button. | G79: User should be able to move media to desired folder | H79: test_MoveMedia
A80: TC79 | B80: Functionality | C80: Media | D80: Create playlist | E80: Verify Create Playlist feature from Material section | F80: 1. Launch JioSignage Sign In Page : https://digitalsignage.jio.com/users/sign_in . 2. Login with valid credentials. 3.Click content management > media 4.Select any existing media(image) file. 5. Go to 3 dot button menu and select create playlist 6. Enter name of the playlist and select duration of media 7. Click Add | G80: User should be able to create a playlist | H80: test_CreatePlaylistFromMediaPage

Sheet Layouts
A1: Sr. No | B1: Test Type | C1: Functionality Name | D1: Sub Functionality | E1: Test Objective | F1: Test Steps | G1: Expected Behavior | H1: Automation test case name | I1: Result | J1: Comment
A2: TC1 | B2: Functionality | C2: Layout Creation | D2: Add new Layout option | E2: Check the add new Layout option | F2: 1. Launch JioSignage (https://digitalsignage.jio.com/users/sign_in) in browser. 2. Login with valid credential. 3. Select Layouts page from home screen via path : Dashboard > Content Management > Layouts. 4. Hover the curser on + icon (Add new layout). 5. Click on the + icon > observe. | G2: 1. Hovering over the option should shows tooltip as 'Add new Layout'. 2. By click on add new option Create Layouts screen should be opened. | H2: test_addNewContent_Option
A3: TC2 | B3: Functionality | C3: Create new Layout | D3: Layout Name | E3: Check Add new Layout name (With Supported input) | F3: 1. Launch JioSignage (https://digitalsignage.jio.com/users/sign_in) in browser. 2. Login with valid credential. 3. Select Layouts page from home screen via path : Dashboard > Content Management > Layouts. 4. Click on the + icon (Add new layout). 5. Provide sample name " 1M. _" (It is a supported input as per specification) in Layout name field . 6. Select Blank Template option > click on "Add" button to save layout. | G3: >User should able to add the Layouts name, Only with supported input characters (Only letters, numbers, dots, spaces and underscores are allowed). Verify that Layout Name field is accepting only supported input as per specification provided (Only letters, numbers, dots, spaces and underscores are allowed). | H3: test_addNewContent
A4: TC3 | B4: Functionality | C4: Create new Layout | D4: Layout Name | E4: Check Add new Layouts name (With non-supported input) | F4: 1. Launch JioSignage (https://digitalsignage.jio.com/users/sign_in) in browser. 2. Login with valid credential. 3. Select Layouts page from home screen via path : Dashboard > Content Management > Layouts. 4. Click on the + icon (Add new layout). 5. Provide sample name " @, $.. " (It is a non-supported input as per specification) in Layout name field . 6. Select Blank Template option > click on "Add" button to save layout. | G4: >It should show error message as '(Only letters, numbers, dots, spaces and underscores are allowed)'. | H4: test_addNewContent_SpecialChar
A5: TC4 | B5: Functionality | C5: Create new Layout | D5: Screen Orientation | E5: Check screen orientation options availability | F5: 1. Launch JioSignage (https://digitalsignage.jio.com/users/sign_in) in browser. 2. Login with valid credential. 3. Select Layouts page from home screen via path : Dashboard > Content Management > Layouts. 4. Observe the Create new Layout screen. 5. Observe the Screen orientation options and switch between Horizontal and Vertical options. | G5: >User should able to select between screen orientation options from Vertical or Horizontal. | H5: test_VerticalHorizontal_option
